Workbook

Sheet C6+ H2S
D1: 14.65 | F1: Pressure Base = | G1: 14.65 | H1: psia
D2: 14.696 | L2: Dry | N2: Dry | S2: Wet | U2: Wet | V2: GPA-2145 | W2: Wet
D3: 14.73 | F3: GPA-2145 | I3: GPA-2145 | J3: Dry | K3: GPA-2145 | L3: Sample | M3: GPA-2145 | N3: Sample | O3: GPA-2145 | S3: Sample | T3: GPA-2145 | U3: Sample | V3: Ideal | W3: Sample | X3: GPA-2145 | Z3: Component
D4: 15.025 | G4: Sample | H4: Sample | I4: Ideal | J4: Sample | K4: Gross | L4: Gross | M4: Net | N4: Net | P4: Sample | R4: Wet Mole | S4: Ideal | T4: Sum | U4: Sum | V4: Relative | W4: Ideal | X4: Molecular | Y4: Component | Z4: Weight | AA4: Component
B5: Actual | C5: Normalized | D5: Normalized | E5: Mole | F5: Cu.Ft./Gal | G5: Ideal | H5: Real | I5: Relative | J5: Ideal | K5: Ideal | L5: Ideal | M5: Ideal | N5: Ideal | O5: Sum | P5: Sum | R5: Fraction | S5: Btu/Cu.Ft. | T5: Factor | U5: Factor | V5: Density | W5: Density | X5: Weight | Y5: Weight | Z5: Fraction | AA5: Weight %
A6: Components | B6: Mole % | C6: Mole % | D6: Mole % | E6: Fraction | F6: Liquid | G6: GPM | H6: GPM | I6: Density | J6: Density | K6: Btu/Cu.Ft. | L6: Btu/Cu.Ft. | M6: Btu/Cu.Ft. | N6: Btu/Cu.Ft. | O6: Factor | P6: Factor | Q6: H2O | R6: =IF(G1=14.65,0.0175,IF(G1=14.696,0.01744,IF(G1=14.73,0.0174,IF(G1=15.025,0.0171)))) -> 0.0175 | S6: 0 | T6: 0.0651 | U6: =ROUND(R6*T6,5) -> 0.00114 | V6: 0.62202 | W6: =ROUND(R6*V6,5) -> 0.01089
A7: H2S | B7: =Report!I18/10000 -> 0 | C7: =B7 -> 0 | D7: =C7 -> 0 | E7: =ROUND(D7/100,6) -> 0 | I7: 1.1767 | J7: =ROUND(E7*I7,5) -> 0 | K7: 637.1 | L7: =ROUND(E7*K7,3) -> 0 | M7: 586.79 | N7: =ROUND(E7*M7,2) -> 0 | O7: 0.0239 | P7: =ROUND(E7*O7,5) -> 0 | Q7: H2S | R7: =ROUND(E7*(1-$R$6),6) -> 0 | S7: =ROUND(K7*R7,3) -> 0 | T7: 0.0239 | U7: =ROUND(R7*T7,5) -> 0 | V7: 1.1767 | W7: =ROUND(R7*V7,5) -> 0 | X7: 34.0809 | Y7: =ROUND(E7*X7,6) -> 0 | Z7: =ROUND(Y7/$Y$20,6) -> #DIV/0! | AA7: =ROUND(Z7*100,4) -> #DIV/0!
A8: He | B8: 0 | C8: =ROUND((100/$B$20)*B8,4) -> #DIV/0! | D8: =C8 -> #DIV/0! | E8: =ROUND(D8/100,6) -> #DIV/0! | I8: 0.1382 | J8: =ROUND(E8*I8,5) -> #DIV/0! | K8: 0 | L8: =ROUND(E8*K8,3) -> #DIV/0! | M8: 0 | N8: =ROUND(E8*M8,2) -> #DIV/0! | O8: 0 | P8: =ROUND(E8*O8,5) -> #DIV/0! | Q8: He | R8: =ROUND(E8*(1-$R$6),6) -> #DIV/0! | S8: =ROUND(K8*R8,3) -> #DIV/0! | T8: 0 | U8: =ROUND(R8*T8,5) -> #DIV/0! | V8: 0.1382 | W8: =ROUND(R8*V8,5) -> #DIV/0! | X8: 4.0026 | Y8: =ROUND(E8*X8,6) -> #DIV/0! | Z8: =ROUND(Y8/$Y$20,6) -> #DIV/0! | AA8: =ROUND(Z8*100,4) -> #DIV/0!
A9: O2 | B9: 0 | C9: =ROUND((100/$B$20)*B9,4) -> #DIV/0! | D9: =C9 -> #DIV/0! | E9: =ROUND(D9/100,6) -> #DIV/0! | I9: 1.1048 | J9: =ROUND(E9*I9,5) -> #DIV/0! | K9: 0 | L9: =ROUND(E9*K9,3) -> #DIV/0! | M9: 0 | N9: =ROUND(E9*M9,2) -> #DIV/0! | O9: 0.0072 | P9: =ROUND(E9*O9,5) -> #DIV/0! | Q9: O2 | R9: =ROUND(E9*(1-$R$6),6) -> #DIV/0! | S9: =ROUND(K9*R9,3) -> #DIV/0! | T9: 0.0072 | U9: =ROUND(R9*T9,5) -> #DIV/0! | V9: 1.1048 | W9: =ROUND(R9*V9,5) -> #DIV/0! | X9: 31.9988 | Y9: =ROUND(E9*X9,6) -> #DIV/0! | Z9: =ROUND(Y9/$Y$20,6) -> #DIV/0! | AA9: =ROUND(Z9*100,4) -> #DIV/0!
A10: N2 | B10: 0 | C10: =ROUND((100/$B$20)*B10,4) -> #DIV/0! | D10: =C10 -> #DIV/0! | E10: =ROUND(D10/100,6) -> #DIV/0! | I10: 0.9672 | J10: =ROUND(E10*I10,5) -> #DIV/0! | K10: 0 | L10: =ROUND(E10*K10,3) -> #DIV/0! | M10: 0 | N10: =ROUND(E10*M10,2) -> #DIV/0! | O10: 0.00442 | P10: =ROUND(E10*O10,5) -> #DIV/0! | Q10: N2 | R10: =ROUND(E10*(1-$R$6),6) -> #DIV/0! | S10: =ROUND(K10*R10,3) -> #DIV/0! | T10: 0.00442 | U10: =ROUND(R10*T10,5) -> #DIV/0! | V10: 0.9672 | W10: =ROUND(R10*V10,5) -> #DIV/0! | X10: 28.0134 | Y10: =ROUND(E10*X10,6) -> #DIV/0! | Z10: =ROUND(Y10/$Y$20,6) -> #DIV/0! | AA10: =ROUND(Z10*100,4) -> #DIV/0!
A11: C1 | B11: 0 | C11: =ROUND((100/$B$20)*B11,4) -> #DIV/0! | D11: =C11+C21 -> #DIV/0! | E11: =ROUND(D11/100,6) -> #DIV/0! | I11: 0.5539 | J11: =ROUND(E11*I11,5) -> #DIV/0! | K11: 1010 | L11: =ROUND(E11*K11,3) -> #DIV/0! | M11: 909.4 | N11: =ROUND(E11*M11,2) -> #DIV/0! | O11: 0.0116 | P11: =ROUND(E11*O11,5) -> #DIV/0! | Q11: C1 | R11: =ROUND(E11*(1-$R$6),6) -> #DIV/0! | S11: =ROUND(K11*R11,3) -> #DIV/0! | T11: 0.0116 | U11: =ROUND(R11*T11,5) -> #DIV/0! | V11: 0.5539 | W11: =ROUND(R11*V11,5) -> #DIV/0! | X11: 16.0425 | Y11: =ROUND(E11*X11,6) -> #DIV/0! | Z11: =ROUND(Y11/$Y$20,6) -> #DIV/0! | AA11: =Z11*100+Z21 -> #DIV/0!
A12: CO2 | B12: 0 | C12: =ROUND((100/$B$20)*B12,4) -> #DIV/0! | D12: =C12 -> #DIV/0! | E12: =ROUND(D12/100,6) -> #DIV/0! | I12: 1.5195 | J12: =ROUND(E12*I12,5) -> #DIV/0! | K12: 0 | L12: =ROUND(E12*K12,3) -> #DIV/0! | M12: 0 | N12: =ROUND(E12*M12,2) -> #DIV/0! | O12: 0.0195 | P12: =ROUND(E12*O12,5) -> #DIV/0! | Q12: CO2 | R12: =ROUND(E12*(1-$R$6),6) -> #DIV/0! | S12: =ROUND(K12*R12,3) -> #DIV/0! | T12: 0.0195 | U12: =ROUND(R12*T12,5) -> #DIV/0! | V12: 1.5195 | W12: =ROUND(R12*V12,5) -> #DIV/0! | X12: 44.0095 | Y12: =ROUND(E12*X12,6) -> #DIV/0! | Z12: =ROUND(Y12/$Y$20,6) -> #DIV/0! | AA12: =ROUND(Z12*100,4) -> #DIV/0!
A13: C2 | B13: 0 | C13: =ROUND((100/$B$20)*B13,4) -> #DIV/0! | D13: =C13 -> #DIV/0! | E13: =ROUND(D13/100,6) -> #DIV/0! | F13: 37.488 | G13: =ROUND(E13/F13*1000*($G$1/14.696),3) -> #DIV/0! | H13: =ROUND(E13/F13*1000*($G$1/14.696)/$L$23,3) -> #DIV/0! | I13: 1.0382 | J13: =ROUND(E13*I13,5) -> #DIV/0! | K13: 1769.7 | L13: =ROUND(E13*K13,3) -> #DIV/0! | M13: 1619 | N13: =ROUND(E13*M13,2) -> #DIV/0! | O13: 0.0238 | P13: =ROUND(E13*O13,5) -> #DIV/0! | Q13: C2 | R13: =ROUND(E13*(1-$R$6),6) -> #DIV/0! | S13: =ROUND(K13*R13,3) -> #DIV/0! | T13: 0.0238 | U13: =ROUND(R13*T13,5) -> #DIV/0! | V13: 1.0382 | W13: =ROUND(R13*V13,5) -> #DIV/0! | X13: 30.069 | Y13: =ROUND(E13*X13,6) -> #DIV/0! | Z13: =ROUND(Y13/$Y$20,6) -> #DIV/0! | AA13: =ROUND(Z13*100,4) -> #DIV/0!
A14: C3 | B14: 0 | C14: =ROUND((100/$B$20)*B14,4) -> #DIV/0! | D14: =C14 -> #DIV/0! | E14: =ROUND(D14/100,6) -> #DIV/0! | F14: 36.391 | G14: =ROUND(E14/F14*1000*($G$1/14.696),3) -> #DIV/0! | H14: =ROUND(E14/F14*1000*($G$1/14.696)/$L$23,3) -> #DIV/0! | I14: 1.5225 | J14: =ROUND(E14*I14,5) -> #DIV/0! | K14: 2516.1 | L14: =ROUND(E14*K14,3) -> #DIV/0! | M14: 2315 | N14: =ROUND(E14*M14,2) -> #DIV/0! | O14: 0.0347 | P14: =ROUND(E14*O14,5) -> #DIV/0! | Q14: C3 | R14: =ROUND(E14*(1-$R$6),6) -> #DIV/0! | S14: =ROUND(K14*R14,3) -> #DIV/0! | T14: 0.0347 | U14: =ROUND(R14*T14,5) -> #DIV/0! | V14: 1.5225 | W14: =ROUND(R14*V14,5) -> #DIV/0! | X14: 44.0956 | Y14: =ROUND(E14*X14,6) -> #DIV/0! | Z14: =ROUND(Y14/$Y$20,6) -> #DIV/0! | AA14: =ROUND(Z14*100,4) -> #DIV/0!
A15: IC4 | B15: 0 | C15: =ROUND((100/$B$20)*B15,4) -> #DIV/0! | D15: =C15 -> #DIV/0! | E15: =ROUND(D15/100,6) -> #DIV/0! | F15: 30.637 | G15: =ROUND(E15/F15*1000*($G$1/14.696),3) -> #DIV/0! | H15: =ROUND(E15/F15*1000*($G$1/14.696)/$L$23,3) -> #DIV/0! | I15: 2.0068 | J15: =ROUND(E15*I15,5) -> #DIV/0! | K15: 3251.9 | L15: =ROUND(E15*K15,3) -> #DIV/0! | M15: 3000 | N15: =ROUND(E15*M15,2) -> #DIV/0! | O15: 0.0441 | P15: =ROUND(E15*O15,5) -> #DIV/0! | Q15: IC4 | R15: =ROUND(E15*(1-$R$6),6) -> #DIV/0! | S15: =ROUND(K15*R15,3) -> #DIV/0! | T15: 0.0441 | U15: =ROUND(R15*T15,5) -> #DIV/0! | V15: 2.0068 | W15: =ROUND(R15*V15,5) -> #DIV/0! | X15: 58.1222 | Y15: =ROUND(E15*X15,6) -> #DIV/0! | Z15: =ROUND(Y15/$Y$20,6) -> #DIV/0! | AA15: =ROUND(Z15*100,4) -> #DIV/0!
A16: NC4 | B16: 0 | C16: =ROUND((100/$B$20)*B16,4) -> #DIV/0! | D16: =C16 -> #DIV/0! | E16: =ROUND(D16/100,6) -> #DIV/0! | F16: 31.801 | G16: =ROUND(E16/F16*1000*($G$1/14.696),3) -> #DIV/0! | H16: =ROUND(E16/F16*1000*($G$1/14.696)/$L$23,3) -> #DIV/0! | I16: 2.0068 | J16: =ROUND(E16*I16,5) -> #DIV/0! | K16: 3262.3 | L16: =ROUND(E16*K16,3) -> #DIV/0! | M16: 3011 | N16: =ROUND(E16*M16,2) -> #DIV/0! | O16: 0.047 | P16: =ROUND(E16*O16,5) -> #DIV/0! | Q16: NC4 | R16: =ROUND(E16*(1-$R$6),6) -> #DIV/0! | S16: =ROUND(K16*R16,3) -> #DIV/0! | T16: 0.047 | U16: =ROUND(R16*T16,5) -> #DIV/0! | V16: 2.0068 | W16: =ROUND(R16*V16,5) -> #DIV/0! | X16: 58.1222 | Y16: =ROUND(E16*X16,6) -> #DIV/0! | Z16: =ROUND(Y16/$Y$20,6) -> #DIV/0! | AA16: =ROUND(Z16*100,4) -> #DIV/0!
A17: IC5 | B17: 0 | C17: =ROUND((100/$B$20)*B17,4) -> #DIV/0! | D17: =C17 -> #DIV/0! | E17: =ROUND(D17/100,6) -> #DIV/0! | F17: 27.414 | G17: =ROUND(E17/F17*1000*($G$1/14.696),3) -> #DIV/0! | H17: =ROUND(E17/F17*1000*($G$1/14.696)/$L$23,3) -> #DIV/0! | I17: 2.4911 | J17: =ROUND(E17*I17,5) -> #DIV/0! | K17: 4000.9 | L17: =ROUND(E17*K17,3) -> #DIV/0! | M17: 3699 | N17: =ROUND(E17*M17,2) -> #DIV/0! | O17: 0.0576 | P17: =ROUND(E17*O17,5) -> #DIV/0! | Q17: IC5 | R17: =ROUND(E17*(1-$R$6),6) -> #DIV/0! | S17: =ROUND(K17*R17,3) -> #DIV/0! | T17: 0.0576 | U17: =ROUND(R17*T17,5) -> #DIV/0! | V17: 2.4911 | W17: =ROUND(R17*V17,5) -> #DIV/0! | X17: 72.1488 | Y17: =ROUND(E17*X17,6) -> #DIV/0! | Z17: =ROUND(Y17/$Y$20,6) -> #DIV/0! | AA17: =ROUND(Z17*100,4) -> #DIV/0!
A18: NC5 | B18: 0 | C18: =ROUND((100/$B$20)*B18,4) -> #DIV/0! | D18: =C18 -> #DIV/0! | E18: =ROUND(D18/100,6) -> #DIV/0! | F18: 27.658 | G18: =ROUND(E18/F18*1000*($G$1/14.696),3) -> #DIV/0! | H18: =ROUND(E18/F18*1000*($G$1/14.696)/$L$23,3) -> #DIV/0! | I18: 2.4911 | J18: =ROUND(E18*I18,5) -> #DIV/0! | K18: 4008.7 | L18: =ROUND(E18*K18,3) -> #DIV/0! | M18: 3707 | N18: =ROUND(E18*M18,2) -> #DIV/0! | O18: 0.0606 | P18: =ROUND(E18*O18,5) -> #DIV/0! | Q18: NC5 | R18: =ROUND(E18*(1-$R$6),6) -> #DIV/0! | S18: =ROUND(K18*R18,3) -> #DIV/0! | T18: 0.0606 | U18: =ROUND(R18*T18,5) -> #DIV/0! | V18: 2.4911 | W18: =ROUND(R18*V18,5) -> #DIV/0! | X18: 72.1488 | Y18: =ROUND(E18*X18,6) -> #DIV/0! | Z18: =ROUND(Y18/$Y$20,6) -> #DIV/0! | AA18: =ROUND(Z18*100,4) -> #DIV/0!
A19: C6+ | B19: 0 | C19: =ROUND((100/$B$20)*B19,4) -> #DIV/0! | D19: =C19 -> #DIV/0! | E19: =ROUND(D19/100,6) -> #DIV/0! | F19: =C26 -> 23.104 | G19: =ROUND(E19/F19*1000*($G$1/14.696),3) -> #DIV/0! | H19: =ROUND(E19/F19*1000*($G$1/14.696)/$L$23,3) -> #DIV/0! | I19: =D26 -> 3.21755 | J19: =ROUND(E19*I19,5) -> #DIV/0! | K19: =E26 -> 5129.22 | L19: =ROUND(E19*K19,3) -> #DIV/0! | M19: =F26 -> 4752 | N19: =ROUND(E19*M19,2) -> #DIV/0! | O19: =G26 -> 0.08637 | P19: =ROUND(E19*O19,5) -> #DIV/0! | Q19: C6+ | R19: =ROUND(E19*(1-$R$6),6) -> #DIV/0! | S19: =ROUND(K19*R19,3) -> #DIV/0! | T19: =G26 -> 0.08637 | U19: =ROUND(R19*T19,5) -> #DIV/0! | V19: =D26 -> 3.21755 | W19: =ROUND(R19*V19,5) -> #DIV/0! | X19: =H26 -> 93.18866 | Y19: =ROUND(E19*X19,6) -> #DIV/0! | Z19: =ROUND(Y19/$Y$20,6) -> #DIV/0! | AA19: =ROUND(Z19*100,4) -> #DIV/0!
A20: Total | B20: =SUM(B7:B19) -> 0 | C20: =SUM(C7:C19) -> #DIV/0! | D20: =SUM(D7:D19) -> #DIV/0! | E20: =SUM(E7:E19) -> #DIV/0! | G20: =ROUND(SUM(G7:G19),3) -> #DIV/0! | H20: =SUM(H7:H19) -> #DIV/0! | J20: =ROUND(SUM(J7:J19),5) -> #DIV/0! | L20: =ROUND(SUM(L7:L19)*($G$1/14.696),3) -> #DIV/0! | N20: =ROUND(SUM(N7:N19)*($G$1/14.696),1) -> #DIV/0! | P20: =ROUND(SUM(P7:P19),5) -> #DIV/0! | R20: =SUM(R6:R19) -> #DIV/0! | S20: =ROUND(SUM(S6:S19)*($G$1/14.696),3) -> #DIV/0! | U20: =ROUND(SUM(U6:U19),5) -> #DIV/0! | W20: =SUM(W6:W19) -> #DIV/0! | Y20: =SUM(Y7:Y19) -> #DIV/0! | Z20: =SUM(Z7:Z19) -> #DIV/0! | AA20: =SUM(AA7:AA19) -> #DIV/0!
C21: =100-C20 -> #DIV/0! | D21: Ideal | E21: . | F21: Net Ideal | G21: Sum | H21: Molar | K21: Z (air) = | L21: =ROUND(1-0.005^2*$G$1,4) -> 0.9996 | Z21: =100-Z20*100 -> #DIV/0!
B22: % | C22: Cu.Ft./Gal | D22: Relative Density | E22: Btu/Cu.Ft. | F22: Btu/Cu.Ft. | G22: Factor | H22: Mass
A23: N-Hexane | B23: 0.6 | C23: 24.38 | D23: 2.9754 | E23: 4755.9 | F23: 4404 | G23: 0.0776 | H23: 86.1754 | K23: Dry Z = | L23: =ROUND(1-(P20^2*$G$1),4) -> #DIV/0! | N23: Wet Z = | O23: =ROUND(1-(U20^2*$G$1),4) -> #DIV/0!
A24: N-Heptane | B24: 0.3 | C24: 21.73 | D24: 3.4597 | E24: 5502.6 | F24: 5100 | G24: 0.0951 | H24: 100.2019 | K24: Real C2+ GPM = | L24: =H20 -> #DIV/0!
A25: N-Octane | B25: 0.1 | C25: 19.57 | D25: 3.944 | E25: 6249 | F25: 5796 | G25: 0.1128 | H25: 114.2285 | K25: Real C3+ GPM= | L25: =H20-H13 -> #DIV/0!
A26: Total | C26: =$B$23*C23+$B$24*C24+$B$25*C25 -> 23.104 | D26: =$B$23*D23+$B$24*D24+$B$25*D25 -> 3.21755 | E26: =$B$23*E23+$B$24*E24+$B$25*E25 -> 5129.22 | F26: =$B$23*F23+$B$24*F24+$B$25*F25 -> 4752 | G26: =$B$23*G23+$B$24*G24+$B$25*G25 -> 0.08637 | H26: =$B$23*H23+$B$24*H24+$B$25*H25 -> 93.18866 | K26: Real C5+ GPM= | L26: =H20-H13-H14-H15-H16 -> #DIV/0!
K27: Real Density = | L27: =ROUND(J20/L23*$L$21,4) -> #DIV/0! | N27: WetReal Density = | O27: =ROUND(W20*L21/O23,4) -> #DIV/0!
K28: Dry Real Btu/Cu.Ft. = | L28: =ROUND(L20/L23,3) -> #DIV/0! | N28: Wet Real But/Cu.Ft. = | O28: =ROUND(S20/O23,3) -> #DIV/0!
K29: C6+ Dry Real BTU/Cu.Ft = | L29: =ROUND(($G$1/14.696)*L19/L23,1) -> #DIV/0!

Sheet Report
H1: 10700 FM 307
H2: Midland, TX 79706
H3: 432-686-2719
H4: www.nattygaslab.com
A5: _____________________________________
A6: Gas Analysis Report | H6: Customer Information
H7: EOG Resources
A8: Method | D8: Analyzed On | E8: 46320.667 | H8: Attn: Brandon Jordan
A9: Analysis # | H9: 1201 S. 3rd St
A10: Cylinder # | D10: Analyzed By | E10: Jared Goldsmith | H10: Jal, NM 88252
A11: _____________________________________
A12: Sample Information
A13: Producer: | E13: Sampled By:
A14: Well/Lease: | E14: Sample Date/Time:
A15: Meter #: | E15: Sample Pressure: | H15: psig
A16: Instrument: | C16: Inficon 1 GC | E16: Sample Temp: | H16: F
A17: Last Inst Verification: | C17: =E8 -> 46320.667 | E17: Ambient Temp: | H17: F
A18: Heating Method: | C18: Oven & Heat Trace | E18: Flow Rate: | G18: MCFD | H18: Field H2S: | J18: PPM
A19: Hexanes + Split | C19: 60/30/10 (C6/C7/C8) | E19: Sample Method: | G19: Purge & Fill | H19: Type:
A20: Remarks: | E20: Effective Start Date: | G20: 46143 | H20: End Date: | I20: 46173
A21: _____________________________________
A22: Base Condition: 14.65 psia and 60° F | E22: Physical Constants per GPA 2145-16
A24: Component | C24: Un-norm Mol % | E24: Norm Mol % | G24: Wt %
A26: H2S* | C26: 0 | E26: ='C6+ H2S'!D7 -> 0 | G26: ='C6+ H2S'!AA7 -> #DIV/0!
A27: Nitrogen | C27: ='C6+ H2S'!B9+'C6+ H2S'!B10 -> 0 | E27: =IF('C6+ H2S'!D10+'C6+ H2S'!D9>0,'C6+ H2S'!D10+'C6+ H2S'!D9,"ND") -> #DIV/0! | G27: =IF('C6+ H2S'!AA10+'C6+ H2S'!AA9>0,'C6+ H2S'!AA10+'C6+ H2S'!AA9,"ND") -> #DIV/0!
A28: Carbon Dioxide | C28: ='C6+ H2S'!B12 -> 0 | E28: =IF('C6+ H2S'!D12>0,'C6+ H2S'!D12,"ND") -> #DIV/0! | G28: =IF('C6+ H2S'!AA12>0,'C6+ H2S'!AA12,"ND") -> #DIV/0! | I28: GPM
A29: Methane | C29: ='C6+ H2S'!B11 -> 0 | E29: =IF('C6+ H2S'!D11>0,'C6+ H2S'!D11,"ND") -> #DIV/0! | G29: =IF('C6+ H2S'!AA11>0,'C6+ H2S'!AA11,"ND") -> #DIV/0! | I29: Real
A30: Ethane | C30: ='C6+ H2S'!B13 -> 0 | E30: =IF('C6+ H2S'!D13>0,'C6+ H2S'!D13,"ND") -> #DIV/0! | G30: =IF('C6+ H2S'!AA13>0,'C6+ H2S'!AA13,"ND") -> #DIV/0! | I30: ='C6+ H2S'!H13 -> #DIV/0!
A31: Propane | C31: ='C6+ H2S'!B14 -> 0 | E31: =IF('C6+ H2S'!D14>0,'C6+ H2S'!D14,"ND") -> #DIV/0! | G31: =IF('C6+ H2S'!AA14>0,'C6+ H2S'!AA14,"ND") -> #DIV/0! | I31: ='C6+ H2S'!H14 -> #DIV/0!
A32: Iso-Butane | C32: ='C6+ H2S'!B15 -> 0 | E32: =IF('C6+ H2S'!D15>0,'C6+ H2S'!D15,"ND") -> #DIV/0! | G32: =IF('C6+ H2S'!AA15>0,'C6+ H2S'!AA15,"ND") -> #DIV/0! | I32: ='C6+ H2S'!H15 -> #DIV/0!
A33: N-Butane | C33: ='C6+ H2S'!B16 -> 0 | E33: =IF('C6+ H2S'!D16>0,'C6+ H2S'!D16,"ND") -> #DIV/0! | G33: =IF('C6+ H2S'!AA16>0,'C6+ H2S'!AA16,"ND") -> #DIV/0! | I33: ='C6+ H2S'!H16 -> #DIV/0!
A34: Iso-Pentane | C34: ='C6+ H2S'!B17 -> 0 | E34: =IF('C6+ H2S'!D17>0,'C6+ H2S'!D17,"ND") -> #DIV/0! | G34: =IF('C6+ H2S'!AA17>0,'C6+ H2S'!AA17,"ND") -> #DIV/0! | I34: ='C6+ H2S'!H17 -> #DIV/0!
A35: N-Pentane | C35: ='C6+ H2S'!B18 -> 0 | E35: =IF('C6+ H2S'!D18>0,'C6+ H2S'!D18,"ND") -> #DIV/0! | G35: =IF('C6+ H2S'!AA18>0,'C6+ H2S'!AA18,"ND") -> #DIV/0! | I35: ='C6+ H2S'!H18 -> #DIV/0!
A36: Hexanes Plus | C36: ='C6+ H2S'!B19 -> 0 | E36: =IF('C6+ H2S'!D19>0,'C6+ H2S'!D19,"ND") -> #DIV/0! | G36: =IF('C6+ H2S'!AA19>0,'C6+ H2S'!AA19,"ND") -> #DIV/0! | I36: ='C6+ H2S'!H19 -> #DIV/0!
C37: =SUM(C26:C36) -> 0 | E37: =SUM(E25:E36) -> #DIV/0! | G37: =SUM(G25:G36) -> #DIV/0! | I37: =SUM(I30:I36) -> #DIV/0!
A38: Gross Heating Value (BTU/ft3 ) | E38: Specific Gravity (air=1.000) | H38: Compressibility Factor (Z)
A39: Dry | B39: Wet | E39: Dry | F39: Wet | H39: Dry | I39: Wet
A40: ='C6+ H2S'!L20 -> #DIV/0! | B40: ='C6+ H2S'!S20 -> #DIV/0! | C40: Ideal | E40: ='C6+ H2S'!J20 -> #DIV/0! | F40: ='C6+ H2S'!W20 -> #DIV/0! | G40: Ideal | H40: ='C6+ H2S'!L23 -> #DIV/0! | I40: ='C6+ H2S'!O23 -> #DIV/0!
A41: ='C6+ H2S'!L28 -> #DIV/0! | B41: ='C6+ H2S'!O28 -> #DIV/0! | C41: Real | E41: ='C6+ H2S'!L27 -> #DIV/0! | F41: ='C6+ H2S'!O27 -> #DIV/0! | G41: Real
G44: *Field H2S rounded to nearest whole ppm
...

Sheet Data Base
A1: Well Name | B1: Station # | C1: Date Sampled | D1: H2S | E1: N | F1: C6+ | G1: C1 | H1: CO2 | I1: C2 | J1: C3 | K1: IC4 | L1: NC4 | M1: IC5 | N1: NC5 | O1: BTU (Dry/Ideal) | P1: BTU (Dry/Real) | Q1: BTU (Wet/Ideal) | R1: BTU(Wet/Real) | S1: GPM (Dry Real C2+) | T1: GPM (Dry Real C3+) | U1: SG (Dry Ideal) | V1: SG (Dry Real) | W1: SG (Wet Ideal) | X1: SG (Wet Real) | Y1: Compressibility (Dry) | Z1: Compressibility (Wet) | AA1: Flow Rate | AB1: Pressure | AC1: Temperature | AD1: Cylinder
A2: =Report!$C$14 -> 0 | B2: =Report!$C$15 -> 0 | C2: =Report!$G$14 -> 0 | D2: ='C6+ H2S'!$D$7 -> 0 | E2: ='C6+ H2S'!$D$10+'C6+ H2S'!$D$9 -> #DIV/0! | F2: ='C6+ H2S'!$D$19 -> #DIV/0! | G2: ='C6+ H2S'!$D$11 -> #DIV/0! | H2: ='C6+ H2S'!$D$12 -> #DIV/0! | I2: ='C6+ H2S'!$D$13 -> #DIV/0! | J2: ='C6+ H2S'!$D$14 -> #DIV/0! | K2: ='C6+ H2S'!$D$15 -> #DIV/0! | L2: ='C6+ H2S'!$D$16 -> #DIV/0! | M2: ='C6+ H2S'!$D$17 -> #DIV/0! | N2: ='C6+ H2S'!$D$18 -> #DIV/0! | O2: ='C6+ H2S'!L20 -> #DIV/0! | P2: ='C6+ H2S'!L28 -> #DIV/0! | Q2: ='C6+ H2S'!S20 -> #DIV/0! | R2: ='C6+ H2S'!O28 -> #DIV/0! | S2: ='C6+ H2S'!L24 -> #DIV/0! | T2: ='C6+ H2S'!L25 -> #DIV/0! | U2: ='C6+ H2S'!J20 -> #DIV/0! | V2: ='C6+ H2S'!L27 -> #DIV/0! | W2: ='C6+ H2S'!W20 -> #DIV/0! | X2: ='C6+ H2S'!O27 -> #DIV/0! | Y2: ='C6+ H2S'!L23 -> #DIV/0! | Z2: ='C6+ H2S'!O23 -> #DIV/0! | AA2: =Report!$F$18 -> 0 | AB2: =Report!$G$15 -> 0 | AC2: =Report!$G$16 -> 0 | AD2: =Report!B10 -> 0

Sheet Masterfile
A1: GQ Source Number | B1: Column Type | C1: From | D1: To | E1: Sample Date | F1: Sample Type | G1: BTU Base | H1: Heating Value | I1: Relative Density | J1: Viscosity | K1: Specific Heat Ratio | L1: HV Pressure Base | M1: Carbon Dioxide | N1: Nitrogen | O1: Methane | P1: Ethane | Q1: Propane | R1: Iso Butane | S1: N Butane | T1: Iso Pentane | U1: N Pentane | V1: Neo Pentane | W1: Hexane | X1: Heptane | Y1: Octane | Z1: Nonane | AA1: Decane | AB1: Argon | AC1: Carbon Monoxide | AD1: Hydrogen | AE1: Oxygen | AF1: Water Vapor | AG1: Hydrogen Sulfide | AH1: Helium | AI1: Hydrogen Sulfide PPM | AJ1: Carbon Sulfoxide PPM | AK1: Methyl Mercaptan PPM | AL1: Ethyl Mercaptan PPM | AM1: Dimethyl Sulfide PPM | AN1: Methyl Sulfide PPM | AO1: Total Sulfur PPM | AP1: Displayed in FlowCal | AQ1: Total GPM Content | AR1: Sample Count | AS1: Heating Value Dry | AT1: Condensate GPM | AU1: Hexane Plus Heating Value | AV1: Field Remarks | AW1: Office Remarks | AX1: Sample Technician | AY1: Analysis Technician | AZ1: Instrument Number | BA1: Sample Pressure | BB1: Sample Temperature | BC1: User defined number 1 | BD1: User defined number 2 | BE1: User defined number 3 | BF1: User defined number 4 | BG1: User defined number 5 | BH1: User defined string 1 | BI1: User defined string 2 | BJ1: User defined string 3 | BK1: User defined string 4 | BL1: User defined string 5 | BM1: Full Well Stream Factor | BN1: Ethane GPM | BO1: Propane GPM | BP1: Iso Butane GPM | BQ1: N Butane GPM | BR1: Iso Pentane GPM | BS1: N Pentane GPM | BT1: Hexane GPM | BU1: Heptane GPM | BV1: Heating Value Wet | BW1: Heating Value As Delivered | BX1: Analysis Date | BY1: Cylinder Number | BZ1: Record Status | CA1: Sample Pressure Gauge | CB1: Atmospheric Pressure | CC1: Octane GPM (c8_gpm) | CD1: Nonane GPM (c9_gpm) | CE1: Decane GPM (c10_gpm | CF1: 26 PSI Gasoline | CG1: Total Mole Percent (total_vol_pct) | CH1: Total Un-Normalized (total_vol_pct_unnormalized) | CI1: Mass Heating Value | CJ1: Wobbe Index - Net | CK1: Wobbe Index - Gross | CL1: Hydrocarbon Dewpoint | CM1: Field HCDP | CN1: Cricondentherm | CO1: Ideal, Gross HV - Dry | CP1: Ideal, Gross HV - Wet | CQ1: Ideal, Gross HV - As Delivered | CR1: Ideal Specific Gravity | CS1: Real, Net HV - Dry | CT1: Real, Net HV - Wet | CU1: Real, Net HV As Delivered | CV1: Temperature Base | CW1: Water Dewpoint | CX1: Total Mass Percent | CY1: User defined number 6 | CZ1: Has Extended Analysis | DA1: Analysis Type | DB1: Free Water | DC1: Condensate | DD1: Compressibility Base | DE1: Compressibility Sample | DF1: Molecular Weight | DG1: Absolute Density | DH1: Density Relative to H2O | DI1: API Gravity | DJ1: Gas/Liquid Volume Ratio | DK1: Mole, Weight or Liquid Volume Percent | DL1: Product Code | DM1: Sample ID | DN1: Ethylene | DO1: Propylene | DP1: Butylenes | DQ1: Base Density Calculation Method | DR1: Set Density By Range | DS1: Analysis Certificate Number | DT1: Absolute Density (liquid, in air) | DU1: Sample Calculation Method | DV1: Vapor Pressure for Sample | DW1: Density Offset | DX1: EVP at 100F | DY1: Mass C1 | DZ1: Mass C2 | EA1: Mass C3 | EB1: Mass IsoC4 | EC1: Mass NC4 | ED1: Mass IsoC5 | EE1: Mass NC5 | EF1: Mass NeoC5 | EG1: Mass C6 | EH1: Mass C7 | EI1: Mass C8 | EJ1: Mass C9 | EK1: Mass C10 | EL1: Mass CO2 | EM1: Mass N2 | EN1: Mass CO | EO1: Mass O2 | EP1: Mass He | EQ1: Mass Ar | ER1: Mass H2O | ES1: Mass H2S | ET1: Mass H2 | EU1: Mass C2H4 | EV1: Mass C3H6 | EW1: Mass C4H8 | EX1: Liquid C1 | EY1: Liquid C2 | EZ1: Liquid C3 | FA1: Liquid IsoC4 | FB1: Liquid NC4 | FC1: Liquid IsoC5 | FD1: Liquid NC5 | FE1: Liquid NeoC5 | FF1: Liquid C6 | FG1: Liquid C7 | FH1: Liquid C8 | FI1: Liquid C9 | FJ1: Liquid C10 | FK1: Liquid CO2 | FL1: Liquid N2 | FM1: Liquid CO | FN1: Liquid O2 | FO1: Liquid He | FP1: Liquid Ar | FQ1: Liquid H2O | FR1: Liquid H2S | FS1: Liquid H2 | FT1: Liquid C2H4 | FU1: Liquid C3H6 | FV1: Liquid C4H8 | FW1: Aromatics | FX1: Mass Aromatics | FY1: Liquid Aromatics | FZ1: SW% | GA1: CSW
A2: =Report!C15 -> 0 | B2: A | C2: =Report!G20 -> 46143 | D2: =Report!I20 -> 46173 | E2: =Report!G14 -> 0 | F2: =IF(Report!I19="Composite","C","S") -> S | G2: W | H2: ='C6+ H2S'!O28 -> #DIV/0! | I2: ='C6+ H2S'!O27 -> #DIV/0! | J2: 6.9e-06 | K2: 1.3 | L2: ='C6+ H2S'!G1 -> 14.65 | M2: ='C6+ H2S'!D12 -> #DIV/0! | N2: ='C6+ H2S'!D10+'C6+ H2S'!D9 -> #DIV/0! | O2: ='C6+ H2S'!D11 -> #DIV/0! | P2: ='C6+ H2S'!D13 -> #DIV/0! | Q2: ='C6+ H2S'!D14 -> #DIV/0! | R2: ='C6+ H2S'!D15 -> #DIV/0! | S2: ='C6+ H2S'!D16 -> #DIV/0! | T2: ='C6+ H2S'!D17 -> #DIV/0! | U2: ='C6+ H2S'!D18 -> #DIV/0! | W2: ='C6+ H2S'!D19 -> #DIV/0! | AG2: ='C6+ H2S'!D7 -> 0 | AI2: =AG2*10000 -> 0 | AQ2: ='C6+ H2S'!H20 -> #DIV/0! | AS2: ='C6+ H2S'!L28 -> #DIV/0! | AT2: ='C6+ H2S'!L26 -> #DIV/0! | AU2: ='C6+ H2S'!E26 -> 5129.22 | AV2: =Report!C20 -> 0 | AX2: =Report!G13 -> 0 | AY2: =Report!E10 -> Jared Goldsmith | BA2: =Report!G15 -> 0 | BB2: =Report!G16 -> 0 | BN2: ='C6+ H2S'!H13 -> #DIV/0! | BO2: ='C6+ H2S'!H14 -> #DIV/0! | BP2: ='C6+ H2S'!H15 -> #DIV/0! | BQ2: ='C6+ H2S'!H16 -> #DIV/0! | BR2: ='C6+ H2S'!H17 -> #DIV/0! | BS2: ='C6+ H2S'!H18 -> #DIV/0! | BT2: ='C6+ H2S'!H19 -> #DIV/0! | BV2: ='C6+ H2S'!O28 -> #DIV/0! | BX2: =Report!E8 -> 46320.667 | BY2: =Report!B10 -> 0 | BZ2: A | CR2: ='C6+ H2S'!W20 -> #DIV/0! | CS2: ='C6+ H2S'!N20 -> #DIV/0! | CV2: 60 | DA2: G | DD2: ='C6+ H2S'!O23 -> #DIV/0! | DF2: ='C6+ H2S'!Y20 -> #DIV/0! | DK2: M | DM2: =Report!B9 -> 0 | DR2: N | DS2: =Report!B9 -> 0 | DU2: =Report!B8 -> 0

Sheet Chromsys
A1: Meter # | B1: Sample Date | C1: Effective Date | D1: Sample Type | E1: Sample ID | F1: Methane | G1: Ethane | H1: Propane | I1: I-Butane | J1: N-Butane | K1: I-Pentane | L1: N-Pentane | M1: Hexane | N1: Heptane | O1: Octane | P1: Nonane | Q1: Decane | R1: Nitrogen | S1: CO2 | T1: H2O | U1: H2S | V1: Hydrogen | W1: CO | X1: Oxygen | Y1: Helium | Z1: Argon | AA1: Gravity | AB1: Pressure Base | AC1: Dry Heating Value | AD1: Saturated Heating Value | AE1: As Delivered Heating Value | AF1: Pressure | AG1: Temperature | AH1: Cylinder # | AI1: Total Un-Normalized Mole% | BR1: Method | BS1: Onsite H2S
A2: =Report!C15 -> 0 | B2: =Report!G14 -> 0 | D2: =IF(Report!I19="Composite","CO","SP") -> SP | F2: ='C6+ H2S'!D11 -> #DIV/0! | G2: ='C6+ H2S'!D13 -> #DIV/0! | H2: ='C6+ H2S'!D14 -> #DIV/0! | I2: ='C6+ H2S'!D15 -> #DIV/0! | J2: ='C6+ H2S'!D16 -> #DIV/0! | K2: ='C6+ H2S'!D17 -> #DIV/0! | L2: ='C6+ H2S'!D18 -> #DIV/0! | M2: ='C6+ H2S'!D19 -> #DIV/0! | R2: ='C6+ H2S'!D10+'C6+ H2S'!D9 -> #DIV/0! | S2: ='C6+ H2S'!D12 -> #DIV/0! | U2: ='C6+ H2S'!D7 -> 0 | AA2: ='C6+ H2S'!L27 -> #DIV/0! | AB2: ='C6+ H2S'!G1 -> 14.65 | AC2: ='C6+ H2S'!L28 -> #DIV/0! | AD2: ='C6+ H2S'!O28 -> #DIV/0! | AF2: =Report!G15 -> 0 | AG2: =Report!G16 -> 0 | AH2: =Report!B10 -> 0 | AI2: ='C6+ H2S'!B20 -> 0 | BR2: =Report!B8 -> 0 | BS2: =Report!I18 -> 0

Sheet FMS
A1: GQ Source Number | B1: From | C1: To | D1: Sample Date | E1: BTU Base | F1: Heating Value Wet | G1: Relative Density (specific gravity) | H1: Carbon Dioxide (co2) | I1: Nitrogen (n2) | J1: H2S | K1: Methane (c1) | L1: Ethane (c2) | M1: Propane (c3) | N1: Iso Butane (iso_c4) | O1: N Butane (n_c4) | P1: Iso Pentane (iso_c5) | Q1: N Pentane (n_c5) | R1: Hexane (c6) | S1: n-Hexane content
A2: =Report!C15 -> 0 | B2: =Report!G14 -> 0 | C2: =Report!G14 -> 0 | D2: =Report!G14 -> 0 | E2: W | F2: ='C6+ H2S'!O28 -> #DIV/0! | G2: ='C6+ H2S'!O27 -> #DIV/0! | H2: ='C6+ H2S'!D12 -> #DIV/0! | I2: ='C6+ H2S'!D10+'C6+ H2S'!D9 -> #DIV/0! | J2: ='C6+ H2S'!D7 -> 0 | K2: ='C6+ H2S'!D11 -> #DIV/0! | L2: ='C6+ H2S'!D13 -> #DIV/0! | M2: ='C6+ H2S'!D14 -> #DIV/0! | N2: ='C6+ H2S'!D15 -> #DIV/0! | O2: ='C6+ H2S'!D16 -> #DIV/0! | P2: ='C6+ H2S'!D17 -> #DIV/0! | Q2: ='C6+ H2S'!D18 -> #DIV/0! | R2: ='C6+ H2S'!D19 -> #DIV/0!

Sheet SM_Data
A1: SampleID | B1: Analysis_Type | C1: Client_ID | D1: Laboratory_Number | E1: Operator_Name | F1: Well_Name | G1: Initials_of_Sampler | H1: Container_Identity | I1: Date_Sampled_Start | J1: Date_Reported | K1: Gauge_Pressure_Source | L1: Temperature_Source | M1: Base_Pressure | N1: Base_Temperature | O1: Methane (C1)_Mole% | P1: Ethane (C2)_Mole% | Q1: Propane (C3)_Mole% | R1: Isobutane (iC4)_Mole% | S1: n-Butane (nC4)_Mole% | T1: Isopentane (iC5)_Mole% | U1: n-Pentane (nC5)_Mole% | V1: Hexanes Plus (C6+)_Mole% | W1: Carbon Dioxide (CO2)_Mole% | X1: Hydrogen Sulfide (H2S)_Mole% | Y1: Nitrogen (N2)_Mole% | Z1: Heating Value_Dry | AA1: Heating Value (Saturated)_Stock Tank Gas | AB1: Total_Dry | AC1: Specific Gravity Total Dry | AD1: Hydrogen Sulfide (H2S)_Onsite | AE1: File_Name
K2: psig | L2: F | M2: psia | N2: F | O2: mole% | P2: mole% | Q2: mole% | R2: mole% | S2: mole% | T2: mole% | U2: mole% | V2: mole% | W2: mole% | X2: mole% | Y2: mole% | Z2: BTU/CF | AA2: BTU/CF | AB2: GPM | AC2: N/A | AD2: ppm (mole)
A3: =Report!B9 -> 0 | B3: USGAS | C3: =Report!C15 -> 0 | D3: =Report!B9 -> 0 | E3: =Report!C13 -> 0 | F3: =Report!C14 -> 0 | G3: =Report!G13 -> 0 | H3: =Report!B10 -> 0 | I3: =Report!G14 -> 0 | J3: =Report!G14 -> 0 | K3: =Report!G15 -> 0 | L3: =Report!G16 -> 0 | M3: ='C6+ H2S'!G1 -> 14.65 | N3: 60 | O3: ='C6+ H2S'!D11 -> #DIV/0! | P3: ='C6+ H2S'!D13 -> #DIV/0! | Q3: ='C6+ H2S'!D14 -> #DIV/0! | R3: ='C6+ H2S'!D15 -> #DIV/0! | S3: ='C6+ H2S'!D16 -> #DIV/0! | T3: ='C6+ H2S'!D17 -> #DIV/0! | U3: ='C6+ H2S'!D18 -> #DIV/0! | V3: ='C6+ H2S'!D19 -> #DIV/0! | W3: ='C6+ H2S'!D12 -> #DIV/0! | X3: ='C6+ H2S'!D7 -> 0 | Y3: ='C6+ H2S'!D10+'C6+ H2S'!D9 -> #DIV/0! | Z3: ='C6+ H2S'!L28 -> #DIV/0! | AA3: ='C6+ H2S'!O28 -> #DIV/0! | AB3: ='C6+ H2S'!L24 -> #DIV/0! | AC3: ='C6+ H2S'!L27 -> #DIV/0! | AD3: ='C6+ H2S'!B7*10000 -> 0 | AE3: {=MID(CELL("filename"),SEARCH("[",CELL("filename"))+1, SEARCH("]",CELL("filename"))-SEARCH("[",CELL("filename"))-6)} -> #N/A
